Workbook

Sheet 👋 Welcome
B2: Coffee Shop Basecamp Week 2 — Financial Model
B4: Your first financial model.
B5: This template is built specifically for coffee shops — not generic businesses.
B8: Step 1: Go to the 📋 Assumptions tab
B9: Fill in the blue cells with your numbers. Don't worry if you're estimating — that's the point. You can always update them.
B11: Step 2: Check the 📊 12-Month P&L tab
B12: This updates automatically based on your assumptions. It shows your projected monthly income and expenses for your first year.
B14: Step 3: Review the 🚀 Break-Even tab
B15: See how many coffees you need to sell every day to cover your costs. This is the most important number.
B17: Step 4: Look at the 🏗️ Startup Costs tab
B18: Fill in the one-time costs to open your shop. This is separate from your monthly running costs.
B20: Colour Guide
B21: ■ Blue numbers | C21: These are your inputs. Change them freely.
B22: ■ Yellow cells | C22: Important inputs — make sure these are filled in.
B23: ■ Black numbers | C23: Calculated automatically. Don't edit these.
B24: ■ Green numbers | C24: Pulled from another tab in this workbook.
B26: 💡 Tip: Your numbers don't need to be perfect. The goal is to practise the thinking, spot the risks, and start building your financial instincts.

Sheet 📋 Assumptions
A2: 📋 Your Assumptions — Fill in the blue cells
A4: A — About Your Shop
B5: Shop name (optional) | D5: Just for your reference
B6: Which type of shop are you planning? | D6: e.g. Neighbourhood Café, Grab-and-Go, Drive-Through, Hybrid
B7: Approximate size of your space (sq ft) | C7: 800 | D7: Your total floor area, including back-of-house
B8: Days open per week | C8: 6 | D8: Most coffee shops are open 6–7 days
B9: Opening time | C9: 6:30 AM | D9: What time do you open?
B10: Closing time | C10: 5:00 PM | D10: What time do you close?
B11: Average trading hours per day | C11: 10 | D11: Hours between open and close that generate sales
A13: B — Daily Sales Assumptions
B14: These numbers drive your revenue projections. Estimate based on your shop type and location.
B15: Morning Rush (e.g. 7–10am)
B16: How many hours is your morning rush? | C16: 3 | D16: Typically 2–4 hours
B17: Transactions per hour during morning rush | C17: 20 | D17: Be realistic — a new shop won't hit capacity straight away
B18: Average spend per customer — morning | C18: 7.5 | D18: Coffee + maybe a pastry
B19: Midday & Afternoon (remaining hours)
B20: Transactions per hour outside peak | C20: 8 | D20: Traffic is much lower outside the morning rush
B21: Average spend per customer — off-peak | C21: 6 | D21: Usually slightly lower than morning
B22: Ramp-up — % of full sales in Month 1
B23: What % of full sales do you expect in Month 1? | C23: 0.5 | D23: Most new shops start at 40–60% of capacity
B24: Months to reach full trading level | C24: 6 | D24: Usually 4–8 months for a new café
A26: C — Cost of Goods (What You Spend Making Each Drink/Item)
B27: Beverage COGS % (coffee, milk, syrups, cups) | C27: 0.28 | D27: Industry range: 25–35%. Includes waste, over-pulling, milk wastage.
B28: Food COGS % (pastries, snacks, food items) | C28: 0.35 | D28: Industry range: 30–40%. Lower if you wholesale-buy finished goods.
B29: % of revenue that is beverages | C29: 0.75 | D29: Most cafés are 70–80% beverages, 20–30% food
A31: D — Staffing Costs
B32: Number of staff on the floor at any one time | C32: 2 | D32: Includes baristas, floor staff. Not you as owner.
B33: Average hourly wage (including taxes/benefits) | C33: 18 | D33: All-in cost per hour per staff member
B34: Total paid staff hours per week | C34: 80 | D34: e.g. 2 staff × 8 hrs × 5 days = 80 hrs
B35: Owner/manager hours per week (unpaid or drawn) | C35: 40 | D35: Your own time — not always a wage in early days
A37: E — Monthly Fixed Costs
B38: These costs happen every month regardless of how busy you are.
B39: Monthly rent (base rent only) | C39: 4500 | D39: This is usually your single biggest fixed cost
B40: Utilities (power, water, gas, internet) | C40: 600 | D40: Coffee equipment uses a lot of power
B41: Insurance | C41: 300 | D41: Public liability, contents, business interruption
B42: POS system / software subscriptions | C42: 150 | D42: Point of sale, scheduling, accounting tools
B43: Marketing & social media | C43: 200 | D43: Budget for early-stage growth
B44: Supplies & smallwares (ongoing) | C44: 150 | D44: Cups, lids, cleaning products, etc.
B45: Loan / equipment finance repayment | C45: 0 | D45: Monthly payment if you financed equipment
B46: Other (accountant, misc) | C46: 200

Sheet 📊 12-Month P&L
A2: 📊 12-Month Projected P&L
C4: Month 1 | D4: Month 2 | E4: Month 3 | F4: Month 4 | G4: Month 5 | H4: Month 6 | I4: Month 7 | J4: Month 8 | K4: Month 9 | L4: Month 10 | M4: Month 11 | N4: Month 12 | O4: FULL YEAR
B5: Trading multiplier (ramp-up) | C5: =MIN(1, '📋 Assumptions'!C23 + (1-'📋 Assumptions'!C23)/MAX(1,'📋 Assumptions'!C24-1)*(1-1)) -> 0.5 | D5: =MIN(1, '📋 Assumptions'!C23 + (1-'📋 Assumptions'!C23)/MAX(1,'📋 Assumptions'!C24-1)*(2-1)) -> 0.6 | E5: =MIN(1, '📋 Assumptions'!C23 + (1-'📋 Assumptions'!C23)/MAX(1,'📋 Assumptions'!C24-1)*(3-1)) -> 0.7 | F5: =MIN(1, '📋 Assumptions'!C23 + (1-'📋 Assumptions'!C23)/MAX(1,'📋 Assumptions'!C24-1)*(4-1)) -> 0.8 | G5: =MIN(1, '📋 Assumptions'!C23 + (1-'📋 Assumptions'!C23)/MAX(1,'📋 Assumptions'!C24-1)*(5-1)) -> 0.9 | H5: =MIN(1, '📋 Assumptions'!C23 + (1-'📋 Assumptions'!C23)/MAX(1,'📋 Assumptions'!C24-1)*(6-1)) -> 1 | I5: =MIN(1, '📋 Assumptions'!C23 + (1-'📋 Assumptions'!C23)/MAX(1,'📋 Assumptions'!C24-1)*(7-1)) -> 1 | J5: =MIN(1, '📋 Assumptions'!C23 + (1-'📋 Assumptions'!C23)/MAX(1,'📋 Assumptions'!C24-1)*(8-1)) -> 1 | K5: =MIN(1, '📋 Assumptions'!C23 + (1-'📋 Assumptions'!C23)/MAX(1,'📋 Assumptions'!C24-1)*(9-1)) -> 1 | L5: =MIN(1, '📋 Assumptions'!C23 + (1-'📋 Assumptions'!C23)/MAX(1,'📋 Assumptions'!C24-1)*(10-1)) -> 1 | M5: =MIN(1, '📋 Assumptions'!C23 + (1-'📋 Assumptions'!C23)/MAX(1,'📋 Assumptions'!C24-1)*(11-1)) -> 1 | N5: =MIN(1, '📋 Assumptions'!C23 + (1-'📋 Assumptions'!C23)/MAX(1,'📋 Assumptions'!C24-1)*(12-1)) -> 1
A6: REVENUE
B7: Total Revenue | C7: =(('📋 Assumptions'!C16*'📋 Assumptions'!C17*'📋 Assumptions'!C18)+(('📋 Assumptions'!C11-'📋 Assumptions'!C16)*'📋 Assumptions'!C20*'📋 Assumptions'!C21))*'📋 Assumptions'!C8*(52/12)*C5 -> 10218 | D7: =(('📋 Assumptions'!C16*'📋 Assumptions'!C17*'📋 Assumptions'!C18)+(('📋 Assumptions'!C11-'📋 Assumptions'!C16)*'📋 Assumptions'!C20*'📋 Assumptions'!C21))*'📋 Assumptions'!C8*(52/12)*D5 -> 12261.6 | E7: =(('📋 Assumptions'!C16*'📋 Assumptions'!C17*'📋 Assumptions'!C18)+(('📋 Assumptions'!C11-'📋 Assumptions'!C16)*'📋 Assumptions'!C20*'📋 Assumptions'!C21))*'📋 Assumptions'!C8*(52/12)*E5 -> 14305.2 | F7: =(('📋 Assumptions'!C16*'📋 Assumptions'!C17*'📋 Assumptions'!C18)+(('📋 Assumptions'!C11-'📋 Assumptions'!C16)*'📋 Assumptions'!C20*'📋 Assumptions'!C21))*'📋 Assumptions'!C8*(52/12)*F5 -> 16348.8 | G7: =(('📋 Assumptions'!C16*'📋 Assumptions'!C17*'📋 Assumptions'!C18)+(('📋 Assumptions'!C11-'📋 Assumptions'!C16)*'📋 Assumptions'!C20*'📋 Assumptions'!C21))*'📋 Assumptions'!C8*(52/12)*G5 -> 18392.4 | H7: =(('📋 Assumptions'!C16*'📋 Assumptions'!C17*'📋 Assumptions'!C18)+(('📋 Assumptions'!C11-'📋 Assumptions'!C16)*'📋 Assumptions'!C20*'📋 Assumptions'!C21))*'📋 Assumptions'!C8*(52/12)*H5 -> 20436 | I7: =(('📋 Assumptions'!C16*'📋 Assumptions'!C17*'📋 Assumptions'!C18)+(('📋 Assumptions'!C11-'📋 Assumptions'!C16)*'📋 Assumptions'!C20*'📋 Assumptions'!C21))*'📋 Assumptions'!C8*(52/12)*I5 -> 20436 | J7: =(('📋 Assumptions'!C16*'📋 Assumptions'!C17*'📋 Assumptions'!C18)+(('📋 Assumptions'!C11-'📋 Assumptions'!C16)*'📋 Assumptions'!C20*'📋 Assumptions'!C21))*'📋 Assumptions'!C8*(52/12)*J5 -> 20436 | K7: =(('📋 Assumptions'!C16*'📋 Assumptions'!C17*'📋 Assumptions'!C18)+(('📋 Assumptions'!C11-'📋 Assumptions'!C16)*'📋 Assumptions'!C20*'📋 Assumptions'!C21))*'📋 Assumptions'!C8*(52/12)*K5 -> 20436 | L7: =(('📋 Assumptions'!C16*'📋 Assumptions'!C17*'📋 Assumptions'!C18)+(('📋 Assumptions'!C11-'📋 Assumptions'!C16)*'📋 Assumptions'!C20*'📋 Assumptions'!C21))*'📋 Assumptions'!C8*(52/12)*L5 -> 20436 | M7: =(('📋 Assumptions'!C16*'📋 Assumptions'!C17*'📋 Assumptions'!C18)+(('📋 Assumptions'!C11-'📋 Assumptions'!C16)*'📋 Assumptions'!C20*'📋 Assumptions'!C21))*'📋 Assumptions'!C8*(52/12)*M5 -> 20436 | N7: =(('📋 Assumptions'!C16*'📋 Assumptions'!C17*'📋 Assumptions'!C18)+(('📋 Assumptions'!C11-'📋 Assumptions'!C16)*'📋 Assumptions'!C20*'📋 Assumptions'!C21))*'📋 Assumptions'!C8*(52/12)*N5 -> 20436 | O7: =SUM(C7:N7) -> 214578
A8: COST OF GOODS SOLD (what you spend making drinks & food)
B9: Beverage COGS | C9: =(C7*'📋 Assumptions'!C29*'📋 Assumptions'!C27) -> 2145.78 | D9: =(D7*'📋 Assumptions'!C29*'📋 Assumptions'!C27) -> 2574.936 | E9: =(E7*'📋 Assumptions'!C29*'📋 Assumptions'!C27) -> 3004.092 | F9: =(F7*'📋 Assumptions'!C29*'📋 Assumptions'!C27) -> 3433.248 | G9: =(G7*'📋 Assumptions'!C29*'📋 Assumptions'!C27) -> 3862.404 | H9: =(H7*'📋 Assumptions'!C29*'📋 Assumptions'!C27) -> 4291.56 | I9: =(I7*'📋 Assumptions'!C29*'📋 Assumptions'!C27) -> 4291.56 | J9: =(J7*'📋 Assumptions'!C29*'📋 Assumptions'!C27) -> 4291.56 | K9: =(K7*'📋 Assumptions'!C29*'📋 Assumptions'!C27) -> 4291.56 | L9: =(L7*'📋 Assumptions'!C29*'📋 Assumptions'!C27) -> 4291.56 | M9: =(M7*'📋 Assumptions'!C29*'📋 Assumptions'!C27) -> 4291.56 | N9: =(N7*'📋 Assumptions'!C29*'📋 Assumptions'!C27) -> 4291.56 | O9: =SUM(C9:N9) -> 45061.38
B10: Food COGS | C10: =(C7*(1-'📋 Assumptions'!C29)*'📋 Assumptions'!C28) -> 894.075 | D10: =(D7*(1-'📋 Assumptions'!C29)*'📋 Assumptions'!C28) -> 1072.89 | E10: =(E7*(1-'📋 Assumptions'!C29)*'📋 Assumptions'!C28) -> 1251.705 | F10: =(F7*(1-'📋 Assumptions'!C29)*'📋 Assumptions'!C28) -> 1430.52 | G10: =(G7*(1-'📋 Assumptions'!C29)*'📋 Assumptions'!C28) -> 1609.335 | H10: =(H7*(1-'📋 Assumptions'!C29)*'📋 Assumptions'!C28) -> 1788.15 | I10: =(I7*(1-'📋 Assumptions'!C29)*'📋 Assumptions'!C28) -> 1788.15 | J10: =(J7*(1-'📋 Assumptions'!C29)*'📋 Assumptions'!C28) -> 1788.15 | K10: =(K7*(1-'📋 Assumptions'!C29)*'📋 Assumptions'!C28) -> 1788.15 | L10: =(L7*(1-'📋 Assumptions'!C29)*'📋 Assumptions'!C28) -> 1788.15 | M10: =(M7*(1-'📋 Assumptions'!C29)*'📋 Assumptions'!C28) -> 1788.15 | N10: =(N7*(1-'📋 Assumptions'!C29)*'📋 Assumptions'!C28) -> 1788.15 | O10: =SUM(C10:N10) -> 18775.575
B11: Total Cost of Goods | C11: =SUM(C9:C10) -> 3039.855 | D11: =SUM(D9:D10) -> 3647.826 | E11: =SUM(E9:E10) -> 4255.797 | F11: =SUM(F9:F10) -> 4863.768 | G11: =SUM(G9:G10) -> 5471.739 | H11: =SUM(H9:H10) -> 6079.71 | I11: =SUM(I9:I10) -> 6079.71 | J11: =SUM(J9:J10) -> 6079.71 | ... N11: =SUM(N9:N10) -> 6079.71 | O11: =SUM(C11:N11) -> 63836.955
B12: GROSS PROFIT | C12: =C7-C11 -> 7178.145 | D12: =D7-D11 -> 8613.774 | E12: =E7-E11 -> 10049.403 | F12: =F7-F11 -> 11485.032 | G12: =G7-G11 -> 12920.661 | H12: =H7-H11 -> 14356.29 | I12: =I7-I11 -> 14356.29 | J12: =J7-J11 -> 14356.29 | ... N12: =N7-N11 -> 14356.29 | O12: =SUM(C12:N12) -> 150741.05
B13: Gross Margin % | C13: =IF(C7=0,0,C12/C7) -> 0.7025 | D13: =IF(D7=0,0,D12/D7) -> 0.7025 | E13: =IF(E7=0,0,E12/E7) -> 0.7025 | F13: =IF(F7=0,0,F12/F7) -> 0.7025 | G13: =IF(G7=0,0,G12/G7) -> 0.7025 | H13: =IF(H7=0,0,H12/H7) -> 0.7025 | I13: =IF(I7=0,0,I12/I7) -> 0.7025 | J13: =IF(J7=0,0,J12/J7) -> 0.7025 | ... N13: =IF(N7=0,0,N12/N7) -> 0.7025 | O13: =IF(SUM(C7:N7)=0,0,SUM(C12:N12)/SUM(C7:N7)) -> 0.7025
A15: OPERATING EXPENSES (monthly running costs)
B16: Labour (paid staff) | C16: ='📋 Assumptions'!C34*'📋 Assumptions'!C33*(52/12) -> 6240 | D16: ='📋 Assumptions'!C34*'📋 Assumptions'!C33*(52/12) -> 6240 | E16: ='📋 Assumptions'!C34*'📋 Assumptions'!C33*(52/12) -> 6240 | F16: ='📋 Assumptions'!C34*'📋 Assumptions'!C33*(52/12) -> 6240 | G16: ='📋 Assumptions'!C34*'📋 Assumptions'!C33*(52/12) -> 6240 | H16: ='📋 Assumptions'!C34*'📋 Assumptions'!C33*(52/12) -> 6240 | I16: ='📋 Assumptions'!C34*'📋 Assumptions'!C33*(52/12) -> 6240 | J16: ='📋 Assumptions'!C34*'📋 Assumptions'!C33*(52/12) -> 6240 | K16: ='📋 Assumptions'!C34*'📋 Assumptions'!C33*(52/12) -> 6240 | L16: ='📋 Assumptions'!C34*'📋 Assumptions'!C33*(52/12) -> 6240 | M16: ='📋 Assumptions'!C34*'📋 Assumptions'!C33*(52/12) -> 6240 | N16: ='📋 Assumptions'!C34*'📋 Assumptions'!C33*(52/12) -> 6240 | O16: =SUM(C16:N16) -> 74880
B17: Labour as % of revenue | C17: =IF(C7=0,0,C16/C7) -> 0.61068702 | D17: =IF(D7=0,0,D16/D7) -> 0.50890585 | E17: =IF(E7=0,0,E16/E7) -> 0.43620502 | F17: =IF(F7=0,0,F16/F7) -> 0.38167939 | G17: =IF(G7=0,0,G16/G7) -> 0.33927057 | H17: =IF(H7=0,0,H16/H7) -> 0.30534351 | I17: =IF(I7=0,0,I16/I7) -> 0.30534351 | J17: =IF(J7=0,0,J16/J7) -> 0.30534351 | ... N17: =IF(N7=0,0,N16/N7) -> 0.30534351 | O17: =IF(SUM(C7:N7)=0,0,SUM(C16:N16)/SUM(C7:N7)) -> 0.34896401
B18: Rent | C18: ='📋 Assumptions'!C39 -> 4500 | D18: ='📋 Assumptions'!C39 -> 4500 | E18: ='📋 Assumptions'!C39 -> 4500 | F18: ='📋 Assumptions'!C39 -> 4500 | G18: ='📋 Assumptions'!C39 -> 4500 | H18: ='📋 Assumptions'!C39 -> 4500 | I18: ='📋 Assumptions'!C39 -> 4500 | J18: ='📋 Assumptions'!C39 -> 4500 | K18: ='📋 Assumptions'!C39 -> 4500 | L18: ='📋 Assumptions'!C39 -> 4500 | M18: ='📋 Assumptions'!C39 -> 4500 | N18: ='📋 Assumptions'!C39 -> 4500 | O18: =SUM(C18:N18) -> 54000
B19: Utilities | C19: ='📋 Assumptions'!C40 -> 600 | D19: ='📋 Assumptions'!C40 -> 600 | E19: ='📋 Assumptions'!C40 -> 600 | F19: ='📋 Assumptions'!C40 -> 600 | G19: ='📋 Assumptions'!C40 -> 600 | H19: ='📋 Assumptions'!C40 -> 600 | I19: ='📋 Assumptions'!C40 -> 600 | J19: ='📋 Assumptions'!C40 -> 600 | K19: ='📋 Assumptions'!C40 -> 600 | L19: ='📋 Assumptions'!C40 -> 600 | M19: ='📋 Assumptions'!C40 -> 600 | N19: ='📋 Assumptions'!C40 -> 600 | O19: =SUM(C19:N19) -> 7200
B20: Insurance | C20: ='📋 Assumptions'!C41 -> 300 | D20: ='📋 Assumptions'!C41 -> 300 | E20: ='📋 Assumptions'!C41 -> 300 | F20: ='📋 Assumptions'!C41 -> 300 | G20: ='📋 Assumptions'!C41 -> 300 | H20: ='📋 Assumptions'!C41 -> 300 | I20: ='📋 Assumptions'!C41 -> 300 | J20: ='📋 Assumptions'!C41 -> 300 | K20: ='📋 Assumptions'!C41 -> 300 | L20: ='📋 Assumptions'!C41 -> 300 | M20: ='📋 Assumptions'!C41 -> 300 | N20: ='📋 Assumptions'!C41 -> 300 | O20: =SUM(C20:N20) -> 3600
B21: POS & Software | C21: ='📋 Assumptions'!C42 -> 150 | D21: ='📋 Assumptions'!C42 -> 150 | E21: ='📋 Assumptions'!C42 -> 150 | F21: ='📋 Assumptions'!C42 -> 150 | G21: ='📋 Assumptions'!C42 -> 150 | H21: ='📋 Assumptions'!C42 -> 150 | I21: ='📋 Assumptions'!C42 -> 150 | J21: ='📋 Assumptions'!C42 -> 150 | K21: ='📋 Assumptions'!C42 -> 150 | L21: ='📋 Assumptions'!C42 -> 150 | M21: ='📋 Assumptions'!C42 -> 150 | N21: ='📋 Assumptions'!C42 -> 150 | O21: =SUM(C21:N21) -> 1800
B22: Marketing | C22: ='📋 Assumptions'!C43 -> 200 | D22: ='📋 Assumptions'!C43 -> 200 | E22: ='📋 Assumptions'!C43 -> 200 | F22: ='📋 Assumptions'!C43 -> 200 | G22: ='📋 Assumptions'!C43 -> 200 | H22: ='📋 Assumptions'!C43 -> 200 | I22: ='📋 Assumptions'!C43 -> 200 | J22: ='📋 Assumptions'!C43 -> 200 | K22: ='📋 Assumptions'!C43 -> 200 | L22: ='📋 Assumptions'!C43 -> 200 | M22: ='📋 Assumptions'!C43 -> 200 | N22: ='📋 Assumptions'!C43 -> 200 | O22: =SUM(C22:N22) -> 2400
B23: Supplies | C23: ='📋 Assumptions'!C44 -> 150 | D23: ='📋 Assumptions'!C44 -> 150 | E23: ='📋 Assumptions'!C44 -> 150 | F23: ='📋 Assumptions'!C44 -> 150 | G23: ='📋 Assumptions'!C44 -> 150 | H23: ='📋 Assumptions'!C44 -> 150 | I23: ='📋 Assumptions'!C44 -> 150 | J23: ='📋 Assumptions'!C44 -> 150 | K23: ='📋 Assumptions'!C44 -> 150 | L23: ='📋 Assumptions'!C44 -> 150 | M23: ='📋 Assumptions'!C44 -> 150 | N23: ='📋 Assumptions'!C44 -> 150 | O23: =SUM(C23:N23) -> 1800
B24: Loan Repayment | C24: ='📋 Assumptions'!C45 -> 0 | D24: ='📋 Assumptions'!C45 -> 0 | E24: ='📋 Assumptions'!C45 -> 0 | F24: ='📋 Assumptions'!C45 -> 0 | G24: ='📋 Assumptions'!C45 -> 0 | H24: ='📋 Assumptions'!C45 -> 0 | I24: ='📋 Assumptions'!C45 -> 0 | J24: ='📋 Assumptions'!C45 -> 0 | K24: ='📋 Assumptions'!C45 -> 0 | L24: ='📋 Assumptions'!C45 -> 0 | M24: ='📋 Assumptions'!C45 -> 0 | N24: ='📋 Assumptions'!C45 -> 0 | O24: =SUM(C24:N24) -> 0
B25: Other | C25: ='📋 Assumptions'!C46 -> 200 | D25: ='📋 Assumptions'!C46 -> 200 | E25: ='📋 Assumptions'!C46 -> 200 | F25: ='📋 Assumptions'!C46 -> 200 | G25: ='📋 Assumptions'!C46 -> 200 | H25: ='📋 Assumptions'!C46 -> 200 | I25: ='📋 Assumptions'!C46 -> 200 | J25: ='📋 Assumptions'!C46 -> 200 | K25: ='📋 Assumptions'!C46 -> 200 | L25: ='📋 Assumptions'!C46 -> 200 | M25: ='📋 Assumptions'!C46 -> 200 | N25: ='📋 Assumptions'!C46 -> 200 | O25: =SUM(C25:N25) -> 2400
B26: Total Operating Expenses | C26: =C16+C18+C19+C20+C21+C22+C23+C24+C25 -> 12340 | D26: =D16+D18+D19+D20+D21+D22+D23+D24+D25 -> 12340 | E26: =E16+E18+E19+E20+E21+E22+E23+E24+E25 -> 12340 | F26: =F16+F18+F19+F20+F21+F22+F23+F24+F25 -> 12340 | G26: =G16+G18+G19+G20+G21+G22+G23+G24+G25 -> 12340 | H26: =H16+H18+H19+H20+H21+H22+H23+H24+H25 -> 12340 | I26: =I16+I18+I19+I20+I21+I22+I23+I24+I25 -> 12340 | J26: =J16+J18+J19+J20+J21+J22+J23+J24+J25 -> 12340 | ... N26: =N16+N18+N19+N20+N21+N22+N23+N24+N25 -> 12340 | O26: =SUM(C26:N26) -> 148080
B28: NET INCOME (LOSS) | C28: =C12-C26 -> -5161.855 | D28: =D12-D26 -> -3726.226 | E28: =E12-E26 -> -2290.597 | F28: =F12-F26 -> -854.968 | G28: =G12-G26 -> 580.661 | H28: =H12-H26 -> 2016.29 | I28: =I12-I26 -> 2016.29 | J28: =J12-J26 -> 2016.29 | ... N28: =N12-N26 -> 2016.29 | O28: =SUM(C28:N28) -> 2661.045
B29: Net Margin % | C29: =IF(C7=0,0,C28/C7) -> -0.50517273 | D29: =IF(D7=0,0,D28/D7) -> -0.30389395 | E29: =IF(E7=0,0,E28/E7) -> -0.16012338 | F29: =IF(F7=0,0,F28/F7) -> -0.052295459 | G29: =IF(G7=0,0,G28/G7) -> 0.031570703 | H29: =IF(H7=0,0,H28/H7) -> 0.098663633 | I29: =IF(I7=0,0,I28/I7) -> 0.098663633 | J29: =IF(J7=0,0,J28/J7) -> 0.098663633 | ... N29: =IF(N7=0,0,N28/N7) -> 0.098663633 | O29: =IF(SUM(C7:N7)=0,0,SUM(C28:N28)/SUM(C7:N7)) -> 0.012401295
B31: 💡 Negative months are normal when you're ramping up. Focus on the trend — are you getting closer to break-even each month?

Sheet 🚀 Break-Even
A2: 🚀 Break-Even Analysis
B4: Break-even is the point where your revenue exactly covers all your costs. It's the minimum you need to not lose money.
A6: Your Key Numbers (from your Assumptions)
B7: Days open per week | C7: ='📋 Assumptions'!C8 -> 6
B8: Average trading hours per day | C8: ='📋 Assumptions'!C11 -> 10
B9: Avg daily transactions (full trading) | C9: =('📋 Assumptions'!C16*'📋 Assumptions'!C17)+(('📋 Assumptions'!C11-'📋 Assumptions'!C16)*'📋 Assumptions'!C20) -> 116
B10: Blended avg ticket | C10: =IF(('📋 Assumptions'!C16*'📋 Assumptions'!C17)+(('📋 Assumptions'!C11-'📋 Assumptions'!C16)*'📋 Assumptions'!C20)=0,0,('📋 Assumptions'!C16*'📋 Assumptions'!C17*'📋 Assumptions'!C18+('📋 Assumptions'!C11-'📋 Assumptions'!C16)*'📋 Assumptions'!C20*'📋 Assumptions'!C21)/(('📋 Assumptions'!C16*'📋 Assumptions'!C17)+(('📋 Assumptions'!C11-'📋 Assumptions'!C16)*'📋 Assumptions'!C20))) -> 6.7758621
B11: Blended COGS % | C11: ='📋 Assumptions'!C29*'📋 Assumptions'!C27+(1-'📋 Assumptions'!C29)*'📋 Assumptions'!C28 -> 0.2975
B12: Contribution margin per $1 of revenue | C12: =1-('📋 Assumptions'!C29*'📋 Assumptions'!C27+(1-'📋 Assumptions'!C29)*'📋 Assumptions'!C28) -> 0.7025
A14: Monthly Costs (pulling from your Assumptions)
B15: Monthly Labour | C15: ='📋 Assumptions'!C34*'📋 Assumptions'!C33*(52/12) -> 6240
B16: Monthly Rent | C16: ='📋 Assumptions'!C39 -> 4500
B17: Monthly Utilities | C17: ='📋 Assumptions'!C40 -> 600
B18: Monthly Insurance | C18: ='📋 Assumptions'!C41 -> 300
B19: Monthly POS & Software | C19: ='📋 Assumptions'!C42 -> 150
B20: Monthly Marketing | C20: ='📋 Assumptions'!C43 -> 200
B21: Monthly Supplies | C21: ='📋 Assumptions'!C44 -> 150
B22: Monthly Loan Repayment | C22: ='📋 Assumptions'!C45 -> 0
B23: Monthly Other | C23: ='📋 Assumptions'!C46 -> 200
B24: Total Monthly Fixed Costs | C24: =SUM(C15:C23) -> 12340
A26: Your Break-Even Numbers
B27: Monthly break-even revenue needed | C27: =IF(C12=0,0,C24/C12) -> 17565.836
B28: Weekly break-even revenue needed | C28: =IF(C12=0,0,(C24/C12)/('📋 Assumptions'!C8*(52/12)/12)) -> 8107.3091
B29: Daily break-even revenue needed | C29: =IF(C12=0,0,(C24/C12)/(('📋 Assumptions'!C8*(52/12)))) -> 675.60909
B30: Transactions per day needed to break even | C30: =IF(C10=0,0,C29/C10) -> 99.708212
B32: How does this compare to your projected daily transactions (from Assumptions → B)?
B33: Your projected daily transactions at full trading: | C33: =C9 -> 116
B35: 📌 Important: The 'rules of thumb' for a healthy coffee shop are: • Labour ≤ 35% of revenue • Rent ≤ 10% of revenue • COGS ≤ 30% of revenue → If you hit all three, you have a shot at 15–20% net margin.

Sheet 🏗️ Startup Costs
A2: 🏗️ Startup Costs — One-Time Costs to Open
B4: These are costs you pay once to get open. They are separate from your monthly running costs. Research real quotes where you can.
A6: Equipment
B7: Espresso machine (commercial) | C7: 12000 | D7: This is your most important piece of equipment. Quality matters.
B8: Grinders (usually 2: espresso + batch) | C8: 4000 | D8: You need at least two. Don't skimp here.
B9: Water filtration system | C9: 1500 | D9: Essential for espresso quality and equipment longevity
B10: Batch brewer / filter coffee equipment | C10: 800 | D10: For drip coffee, cold brew setup, etc.
B11: Bar refrigeration (under-counter) | C11: 2000 | D11: For milk, food, cold drinks storage under the bar
B12: Other equipment (blender, steamer, etc.) | C12: 500
B13: Equipment Subtotal | C13: =SUM(C7:C12) -> 20800
A15: Bar & Space Build-Out
B16: Bar fabrication & installation | C16: 15000 | D16: Custom counter, cabinetry, plumbing to bar. Prices vary hugely.
B17: Electrical upgrades | C17: 3000 | D17: Commercial coffee equipment draws serious power
B18: Plumbing | C18: 2000 | D18: Drainage, water supply to bar
B19: Flooring | C19: 3000
B20: Painting & décor | C20: 2000
B21: Signage (exterior & interior) | C21: 2500 | D21: First impression — worth investing in
B22: Bar & Space Build-Out Subtotal | C22: =SUM(C16:C21) -> 27500
A24: Furniture & Fixtures
B25: Tables and chairs / seating | C25: 4000
B26: Lighting fixtures | C26: 1500 | D26: Lighting sets mood and is often underbudgeted
B27: Display cases / shelving | C27: 1000
B28: Furniture & Fixtures Subtotal | C28: =SUM(C25:C27) -> 6500
A30: Tech & Systems
B31: POS system hardware (tablet, reader, printer) | C31: 800 | D31: e.g. Square, Lightspeed, Toast
B32: Computer / admin setup | C32: 500
B33: Security system / cameras | C33: 600
B34: Tech & Systems Subtotal | C34: =SUM(C31:C33) -> 1900
A36: Opening Inventory & Smallwares
B37: Opening coffee inventory (beans, syrups, milk) | C37: 1500 | D37: Enough for 2–4 weeks trading
B38: Smallwares (tampers, jugs, cloths, cleaning gear) | C38: 1000
B39: Packaging (cups, lids, bags, sleeves) | C39: 800
B40: Food / pastry opening stock | C40: 500
B41: Opening Inventory & Smallwares Subtotal | C41: =SUM(C37:C40) -> 3800
A43: Pre-Opening Costs
B44: Permits & licences (food, business, signage) | C44: 1000 | D44: Varies widely by location — research your local council
B45: Lease deposit (often 2–3 months rent) | C45: 9000 | D45: Usually the biggest single upfront cost
B46: Rent during fit-out (before opening) | C46: 4500 | D46: You're often paying rent while you're building
B47: Legal fees (lease review) | C47: 1500 | D47: Always get the lease reviewed by a lawyer
B48: Insurance (first year upfront) | C48: 2500
...
